Workbook
Name ___INDEX_SHEET___ASAP_Utilities: #REF!
Name ___INDEX_SHEET___ASAP_Utilities: #REF!

Sheet master
A1: =Test!A7 | B1: =Test!A8 | C1: =Test!A9 | D1: =Test!A10 | E1: =Test!A14 | F1: =Test!A15 | G1: =Test!A17 | H1: =Test!A18 | I1: =Test!A19 | J1: =Test!A20 | K1: =Test!A21 | L1: =Test!A22 | M1: =Test!A23 | N1: =Test!A24 | O1: =Test!A25 | P1: =Test!A27 | Q1: =Test!A28 | R1: =Test!A29 | S1: =Test!A30 | T1: =Test!A31 | U1: =Test!A32 | V1: =Test!A33 | W1: =Test!A34 | X1: =Test!A35 | Y1: =Test!A36 | Z1: =Test!A37 | AA1: =Test!A38 | AB1: =Test!A39 | AC1: =Test!A40 | AD1: =Test!A41 | AE1: =Test!A42 | AF1: =Test!A43 | AG1: =Test!A44 | AH1: =Test!A45

Sheet Test
A1: Working Paper
A2: Satker xxx
A3: Purpose ;……
A4: Jalan xxxx
A5: BM 2850 AP
A6: Data Transaksi Penjualan | B6: Objek Penilaian
A7: Photo
A8: Information
A9: Linked
A10: Price
A11: PENYESUAIAN 1 (PENYESUAIAN TRANSAKSI)
A12: Faktor-faktor Penyesuaian | B12: Objek Penilaian
A14: Jenis Transaksi | B14: Penilaian
A15: Waktu Transaksi | B15: 44348
A16: Dokumen legalitas :
A17: BPKB | B17: Ada
A18: STNK | B18: Tidak ada
A19: Pajak Kendaraan | B19: Mati
A20: Jml Penyesuaian Transaksional
A21: Indikasi Nilai Kendaraan 1
A22: PENYESUAIAN 2 (PENYESUAIAN PROPERTI)
A23: Merk / Tipe | B23: Yamaha / RX King
A24: Tahun Pembuatan | B24: 2007
A25: Kondisi Mesin | B25: Baik
A27: Kondisi Bodi | B27: Rusak Berat
A28: Isi Silinder | B28: 160 cc
A29: Bahan Bakar | B29: Bensin
A30: Warna | B30: Hitam
A31: Spesifikasi Bodi :
A32: Jok | B32: Baik sekali
A33: Ban | B33: Baik, halus
A34: Velg | B34: Racing, baik
A35: Spion | B35: Ada, baik
A36: Lampu Depan | B36: Ada, baik
A37: Lampu Belakang | B37: Ada, rusak ringan
A38: Rem | B38: Baik
A39: Knalpot | B39: Baik sekali
A40: Cat | B40: Baik
A41: Kelistrikan/Accu | B41: Rusak ringan (kurang normal)
A42: Kelengkapan lainnya :
...
