Workbook

Sheet Data
A6: ITEM | B6: Supplier ID | C6: DESCRIPTION | D6: UOM | E6: SUPPLIER_NAME | F6: SUPPLIER_SITE_NAME | G6: 44151 | H6: 44158 | I6: 44165 | J6: 44172 | K6: 44179 | L6: 44186 | M6: 44200 | N6: 44207 | O6: 44214 | P6: 44221 | Q6: 44228 | R6: 44235 | S6: 44242 | T6: 44249 | U6: 44256 | V6: 44263 | W6: 44270 | X6: 44277 | Y6: 44284 | Z6: 44291 | AA6: 44298 | AB6: 44305 | AC6: 44312 | AD6: 44319 | AE6: 44326 | AF6: 44333 | AG6: 44340 | AH6: 44347 | AI6: 44354 | AJ6: 44361 | AK6: 44368 | AL6: 44375 | AM6: 44382 | AN6: 44389 | AO6: 44396 | AP6: 44410 | AQ6: 44417 | AR6: 44424 | AS6: 44431 | AT6: 44438 | AU6: 44466 | AV6: 44494 | AW6: 44529 | AX6: 44557
A7: 1091A39H20 | B7: 21 | C7: TUBE .875ID 1.375OD RUBBER | D7: FT | E7: SAMPLE | F7: US | G7: 2280 | H7: 0 | I7: 5928 | J7: 0 | K7: 3876 | L7: 0 | M7: 0 | N7: 2280 | O7: 0 | P7: 2508 | Q7: 0 | R7: 2736 | S7: 0 | T7: 2736 | U7: 0 | V7: 2964 | W7: 0 | X7: 2736 | Y7: 0 | Z7: 2280 | AA7: 0 | AB7: 2508 | AC7: 0 | AD7: 2964 | AE7: 0 | AF7: 2964 | AG7: 0 | AH7: 3192 | AI7: 0 | AJ7: 3420 | AK7: 0 | AL7: 3192 | AM7: 0 | AN7: 3420 | AO7: 0 | AP7: 3420 | AQ7: 0 | AR7: 4788 | AS7: 0 | AT7: 0 | AU7: 5700 | AV7: 6612 | AW7: 8664 | AX7: 5472
A8: 1091A39H27 | B8: 21 | C8: TUBE .500ID 1.250OD RUBBER | D8: FT | E8: SAMPLE | F8: US | G8: 2412 | H8: 0 | I8: 0 | J8: 0 | K8: 3216 | L8: 0 | M8: 0 | N8: 0 | O8: 0 | P8: 4020 | Q8: 0 | R8: 0 | S8: 0 | T8: 3618 | U8: 0 | V8: 0 | W8: 0 | X8: 2814 | Y8: 0 | Z8: 0 | AA8: 0 | AB8: 3618 | AC8: 0 | AD8: 0 | AE8: 0 | AF8: 3216 | AG8: 0 | AH8: 0 | AI8: 0 | AJ8: 3618 | AK8: 0 | AL8: 0 | AM8: 0 | AN8: 3618 | AO8: 0 | AP8: 0 | AQ8: 4020 | AR8: 0 | AS8: 0 | AT8: 0 | AU8: 4020 | AV8: 4422 | AW8: 4422 | AX8: 2814
A9: 1091A39H28 | B9: 21 | C9: TUBE .625ID 1.375OD RUBBER | D9: FT | E9: SAMPLE | F9: US | G9: 348 | H9: 0 | I9: 0 | J9: 0 | K9: 0 | L9: 0 | M9: 0 | N9: 0 | O9: 0 | P9: 348 | Q9: 0 | R9: 0 | S9: 0 | T9: 0 | U9: 0 | V9: 0 | W9: 0 | X9: 0 | Y9: 0 | Z9: 0 | AA9: 0 | AB9: 0 | AC9: 0 | AD9: 348 | AE9: 0 | AF9: 0 | AG9: 0 | AH9: 0 | AI9: 0 | AJ9: 0 | AK9: 0 | AL9: 0 | AM9: 0 | AN9: 0 | AO9: 0 | AP9: 0 | AQ9: 0 | AR9: 348 | AS9: 0 | AT9: 0 | AU9: 0 | AV9: 0 | AW9: 348 | AX9: 0
A10: 1091A39H34 | B10: 21 | C10: TUBE .375ID 1.125OD RUBBER SPLIT | D10: FT | E10: SAMPLE | F10: US | G10: 0 | H10: 0 | I10: 0 | J10: 0 | K10: 0 | L10: 0 | M10: 0 | N10: 0 | O10: 0 | P10: 0 | Q10: 0 | R10: 0 | S10: 570 | T10: 0 | U10: 0 | V10: 0 | W10: 0 | X10: 0 | Y10: 0 | Z10: 0 | AA10: 570 | AB10: 0 | AC10: 0 | AD10: 0 | AE10: 0 | AF10: 0 | AG10: 0 | AH10: 0 | AI10: 570 | AJ10: 0 | AK10: 0 | AL10: 0 | AM10: 0 | AN10: 0 | AO10: 0 | AP10: 570 | AQ10: 0 | AR10: 0 | AS10: 0 | AT10: 0 | AU10: 570 | AV10: 0 | AW10: 570 | AX10: 0
A11: 2H05836001 | B11: 21 | C11: TRIM - EDGE W/ METAL CORE, 5/8", L 150 | D11: EA | E11: SAMPLE | F11: US | G11: 0 | H11: 110 | I11: 0 | J11: 0 | K11: 0 | L11: 0 | M11: 0 | N11: 0 | O11: 110 | P11: 0 | Q11: 0 | R11: 0 | S11: 110 | T11: 0 | U11: 0 | V11: 0 | W11: 0 | X11: 110 | Y11: 0 | Z11: 0 | AA11: 0 | AB11: 0 | AC11: 110 | AD11: 0 | AE11: 0 | AF11: 0 | AG11: 0 | AH11: 0 | AI11: 110 | AJ11: 0 | AK11: 0 | AL11: 0 | AM11: 0 | AN11: 110 | AO11: 0 | AP11: 0 | AQ11: 0 | AR11: 110 | AS11: 0 | AT11: 0 | AU11: 110 | AV11: 110 | AW11: 110 | AX11: 0
A12: 2H05836002 | B12: 21 | C12: TRIM - EDGE W/ METAL CORE, 5/8", L 120 | D12: EA | E12: SAMPLE | F12: US | G12: 0 | H12: 0 | I12: 0 | J12: 110 | K12: 0 | L12: 0 | M12: 0 | N12: 0 | O12: 0 | P12: 110 | Q12: 0 | R12: 0 | S12: 0 | T12: 110 | U12: 0 | V12: 0 | W12: 0 | X12: 110 | Y12: 0 | Z12: 0 | AA12: 0 | AB12: 0 | AC12: 0 | AD12: 110 | AE12: 0 | AF12: 0 | AG12: 0 | AH12: 0 | AI12: 110 | AJ12: 0 | AK12: 0 | AL12: 0 | AM12: 0 | AN12: 110 | AO12: 0 | AP12: 0 | AQ12: 0 | AR12: 0 | AS12: 110 | AT12: 0 | AU12: 110 | AV12: 0 | AW12: 110 | AX12: 110
A13: 2H05836003 | B13: 21 | C13: TRIM - EDGE W/ METAL CORE, 5/8", L 299 | D13: EA | E13: SAMPLE | F13: US | G13: 0 | H13: 0 | I13: 0 | J13: 0 | K13: 0 | L13: 110 | M13: 0 | N13: 0 | O13: 0 | P13: 0 | Q13: 110 | R13: 0 | S13: 0 | T13: 0 | U13: 0 | V13: 110 | W13: 0 | X13: 0 | Y13: 0 | Z13: 0 | AA13: 110 | AB13: 0 | AC13: 0 | AD13: 0 | AE13: 0 | AF13: 110 | AG13: 0 | AH13: 0 | AI13: 0 | AJ13: 0 | AK13: 110 | AL13: 0 | AM13: 0 | AN13: 0 | AO13: 0 | AP13: 110 | AQ13: 0 | AR13: 0 | AS13: 0 | AT13: 0 | AU13: 110 | AV13: 110 | AW13: 110 | AX13: 110
A14: 2H05836004 | B14: 21 | C14: TRIM-EDGE W/ METAL CORE, 5/8", L 555 | D14: EA | E14: SAMPLE | F14: US | G14: 0 | H14: 0 | I14: 0 | J14: 0 | K14: 0 | L14: 0 | M14: 0 | N14: 110 | O14: 0 | P14: 0 | Q14: 0 | R14: 110 | S14: 0 | T14: 0 | U14: 0 | V14: 0 | W14: 110 | X14: 0 | Y14: 0 | Z14: 0 | AA14: 0 | AB14: 110 | AC14: 0 | AD14: 0 | AE14: 0 | AF14: 0 | AG14: 110 | AH14: 0 | AI14: 0 | AJ14: 0 | AK14: 0 | AL14: 110 | AM14: 0 | AN14: 0 | AO14: 0 | AP14: 0 | AQ14: 110 | AR14: 0 | AS14: 0 | AT14: 0 | AU14: 110 | AV14: 110 | AW14: 110 | AX14: 0
A15: 2H05836005 | B15: 21 | C15: TRIM - EDGE W/ METAL CORE, 5/8", L 169 | D15: EA | E15: SAMPLE | F15: US | G15: 0 | H15: 0 | I15: 0 | J15: 0 | K15: 0 | L15: 110 | M15: 0 | N15: 0 | O15: 0 | P15: 0 | Q15: 110 | R15: 0 | S15: 0 | T15: 0 | U15: 0 | V15: 110 | W15: 0 | X15: 0 | Y15: 0 | Z15: 0 | AA15: 110 | AB15: 0 | AC15: 0 | AD15: 0 | AE15: 0 | AF15: 110 | AG15: 0 | AH15: 0 | AI15: 0 | AJ15: 0 | AK15: 110 | AL15: 0 | AM15: 0 | AN15: 0 | AO15: 0 | AP15: 110 | AQ15: 0 | AR15: 0 | AS15: 0 | AT15: 0 | AU15: 110 | AV15: 110 | AW15: 110 | AX15: 110
A16: 2H05836006 | B16: 21 | C16: TRIM - EDGE W/ METAL CORE, 5/8", L 105 | D16: EA | E16: SAMPLE | F16: US | G16: 0 | H16: 0 | I16: 0 | J16: 0 | K16: 0 | L16: 0 | M16: 0 | N16: 0 | O16: 110 | P16: 0 | Q16: 0 | R16: 0 | S16: 110 | T16: 0 | U16: 0 | V16: 0 | W16: 110 | X16: 0 | Y16: 0 | Z16: 0 | AA16: 0 | AB16: 0 | AC16: 110 | AD16: 0 | AE16: 0 | AF16: 0 | AG16: 0 | AH16: 110 | AI16: 0 | AJ16: 0 | AK16: 0 | AL16: 0 | AM16: 110 | AN16: 0 | AO16: 0 | AP16: 0 | AQ16: 0 | AR16: 110 | AS16: 0 | AT16: 0 | AU16: 110 | AV16: 110 | AW16: 110 | AX16: 0
A17: 2H05836007 | B17: 21 | C17: TRIM - EDGE W/ METAL CORE, 5/8", L 240 | D17: EA | E17: SAMPLE | F17: US | G17: 0 | H17: 0 | I17: 0 | J17: 0 | K17: 0 | L17: 0 | M17: 0 | N17: 110 | O17: 0 | P17: 0 | Q17: 0 | R17: 110 | S17: 0 | T17: 0 | U17: 0 | V17: 0 | W17: 110 | X17: 0 | Y17: 0 | Z17: 0 | AA17: 0 | AB17: 110 | AC17: 0 | AD17: 0 | AE17: 0 | AF17: 0 | AG17: 0 | AH17: 110 | AI17: 0 | AJ17: 0 | AK17: 0 | AL17: 0 | AM17: 110 | AN17: 0 | AO17: 0 | AP17: 0 | AQ17: 110 | AR17: 0 | AS17: 0 | AT17: 0 | AU17: 110 | AV17: 110 | AW17: 110 | AX17: 0
A18: 2H05836008 | B18: 21 | C18: TRIM - EDGE W/ METAL CORE, 5/8", L 30 | D18: EA | E18: SAMPLE | F18: US | G18: 0 | H18: 0 | I18: 0 | J18: 0 | K18: 110 | L18: 0 | M18: 0 | N18: 0 | O18: 0 | P18: 110 | Q18: 0 | R18: 0 | S18: 0 | T18: 0 | U18: 110 | V18: 0 | W18: 0 | X18: 0 | Y18: 0 | Z18: 110 | AA18: 0 | AB18: 0 | AC18: 0 | AD18: 0 | AE18: 110 | AF18: 0 | AG18: 0 | AH18: 0 | AI18: 0 | AJ18: 110 | AK18: 0 | AL18: 0 | AM18: 0 | AN18: 0 | AO18: 110 | AP18: 0 | AQ18: 0 | AR18: 0 | AS18: 0 | AT18: 110 | AU18: 0 | AV18: 110 | AW18: 110 | AX18: 110
... A22: 2H24016003 | B22: 21 | C22: GROMMET -10mm | D22: EA | E22: SAMPLE | F22: US | G22: 0 | H22: 0 | I22: 0 | J22: 0 | K22: 0 | L22: 0 | M22: 0 | N22: 0 | O22: 0 | P22: 0 | Q22: 0 | R22: 0 | S22: 0 | T22: 0 | U22: 0 | V22: 0 | W22: 0 | X22: 0 | Y22: 0 | Z22: 0 | AA22: 0 | AB22: 0 | AC22: 0 | AD22: 0 | AE22: 0 | AF22: 0 | AG22: 0 | AH22: 0 | AI22: 0 | AJ22: 0 | AK22: 0 | AL22: 0 | AM22: 0 | AN22: 0 | AO22: 0 | AP22: 0 | AQ22: 0 | AR22: 0 | AS22: 0 | AT22: 0 | AU22: 0 | AV22: 0 | AW22: 0 | AX22: 0
A23: 332918 | B23: 21 | C23: GASKET SILL | D23: EA | E23: SAMPLE | F23: US | G23: 0 | H23: 0 | I23: 0 | J23: 0 | K23: 0 | L23: 0 | M23: 0 | N23: 0 | O23: 0 | P23: 0 | Q23: 0 | R23: 0 | S23: 0 | T23: 0 | U23: 0 | V23: 0 | W23: 0 | X23: 0 | Y23: 0 | Z23: 0 | AA23: 0 | AB23: 0 | AC23: 0 | AD23: 0 | AE23: 0 | AF23: 0 | AG23: 0 | AH23: 0 | AI23: 0 | AJ23: 0 | AK23: 0 | AL23: 0 | AM23: 0 | AN23: 0 | AO23: 0 | AP23: 0 | AQ23: 0 | AR23: 0 | AS23: 0 | AT23: 0 | AU23: 0 | AV23: 0 | AW23: 0 | AX23: 0
A24: 335063 | B24: 21 | C24: GASKET SKINS 25FT | D24: EA | E24: SAMPLE | F24: US | G24: 0 | H24: 0 | I24: 0 | J24: 0 | K24: 0 | L24: 0 | M24: 0 | N24: 0 | O24: 0 | P24: 0 | Q24: 0 | R24: 0 | S24: 0 | T24: 0 | U24: 0 | V24: 0 | W24: 0 | X24: 0 | Y24: 0 | Z24: 0 | AA24: 0 | AB24: 0 | AC24: 0 | AD24: 0 | AE24: 0 | AF24: 0 | AG24: 0 | AH24: 0 | AI24: 0 | AJ24: 0 | AK24: 0 | AL24: 0 | AM24: 0 | AN24: 0 | AO24: 0 | AP24: 0 | AQ24: 0 | AR24: 0 | AS24: 0 | AT24: 0 | AU24: 0 | AV24: 0 | AW24: 0 | AX24: 0
A25: 335129 | B25: 21 | C25: INSULATION MUFFLER | D25: EA | E25: SAMPLE | F25: US | G25: 0 | H25: 0 | I25: 0 | J25: 0 | K25: 0 | L25: 0 | M25: 0 | N25: 0 | O25: 0 | P25: 0 | Q25: 0 | R25: 0 | S25: 0 | T25: 0 | U25: 0 | V25: 0 | W25: 0 | X25: 0 | Y25: 0 | Z25: 0 | AA25: 0 | AB25: 0 | AC25: 0 | AD25: 0 | AE25: 0 | AF25: 0 | AG25: 0 | AH25: 0 | AI25: 0 | AJ25: 0 | AK25: 0 | AL25: 0 | AM25: 0 | AN25: 0 | AO25: 0 | AP25: 0 | AQ25: 0 | AR25: 0 | AS25: 0 | AT25: 0 | AU25: 0 | AV25: 0 | AW25: 0 | AX25: 0
A26: 5D47857G01 | B26: 21 | C26: GASKET-SILL | D26: EA | E26: SAMPLE | F26: US | G26: 453 | H26: 0 | I26: 514 | J26: 522 | K26: 527 | L26: 315 | M26: 0 | N26: 591 | O26: 530 | P26: 530 | Q26: 580 | R26: 530 | S26: 530 | T26: 530 | U26: 435 | V26: 435 | W26: 430 | X26: 435 | Y26: 348 | Z26: 435 | AA26: 435 | AB26: 435 | AC26: 435 | AD26: 435 | AE26: 435 | AF26: 435 | AG26: 435 | AH26: 480 | AI26: 600 | AJ26: 600 | AK26: 600 | AL26: 360 | AM26: 600 | AN26: 600 | AO26: 600 | AP26: 600 | AQ26: 600 | AR26: 600 | AS26: 1198 | AT26: 0 | AU26: 2282 | AV26: 2160 | AW26: 2640 | AX26: 1680
A27: 617597 | B27: 21 | C27: SLEEVE - HOLD DOWN, DRAIN PAN | D27: EA | E27: SAMPLE | F27: US | G27: 0 | H27: 0 | I27: 0 | J27: 0 | K27: 0 | L27: 0 | M27: 0 | N27: 0 | O27: 0 | P27: 0 | Q27: 0 | R27: 0 | S27: 0 | T27: 0 | U27: 0 | V27: 0 | W27: 0 | X27: 0 | Y27: 0 | Z27: 0 | AA27: 0 | AB27: 0 | AC27: 0 | AD27: 0 | AE27: 0 | AF27: 0 | AG27: 0 | AH27: 0 | AI27: 0 | AJ27: 0 | AK27: 0 | AL27: 0 | AM27: 0 | AN27: 0 | AO27: 0 | AP27: 0 | AQ27: 0 | AR27: 0 | AS27: 0 | AT27: 0 | AU27: 0 | AV27: 0 | AW27: 0 | AX27: 0
A28: 998562 | B28: 21 | C28: STRIP 25 FEET | D28: EA | E28: SAMPLE | F28: US | G28: 0 | H28: 0 | I28: 0 | J28: 0 | K28: 0 | L28: 0 | M28: 0 | N28: 0 | O28: 0 | P28: 0 | Q28: 0 | R28: 0 | S28: 0 | T28: 0 | U28: 0 | V28: 0 | W28: 0 | X28: 0 | Y28: 0 | Z28: 0 | AA28: 0 | AB28: 0 | AC28: 0 | AD28: 0 | AE28: 0 | AF28: 0 | AG28: 0 | AH28: 0 | AI28: 0 | AJ28: 0 | AK28: 0 | AL28: 0 | AM28: 0 | AN28: 0 | AO28: 0 | AP28: 0 | AQ28: 0 | AR28: 0 | AS28: 0 | AT28: 0 | AU28: 0 | AV28: 0 | AW28: 0 | AX28: 0

Sheet Transpose
A2: ITEM | B2: Date | C2: Qty's
A3: =Data!$A$7 | B3: =Data!$G$6 | C3: =Data!G7
A4: =Data!$A$7 | B4: =Data!$H$6 | C4: =Data!H7
A5: =Data!$A$7 | B5: =Data!$I$6 | C5: =Data!I7
A6: =Data!$A$7 | B6: =Data!$J$6 | C6: =Data!J7
A7: =Data!$A$7 | B7: =Data!$K$6 | C7: =Data!K7
A8: =Data!$A$7 | B8: =Data!$L$6 | C8: =Data!L7
A9: =Data!$A$7 | B9: =Data!$M$6 | C9: =Data!M7
A10: =Data!$A$7 | B10: =Data!$N$6 | C10: =Data!N7
A11: =Data!$A$7 | B11: =Data!$O$6 | C11: =Data!O7
A12: =Data!$A$7 | B12: =Data!$P$6 | C12: =Data!P7
A13: =Data!$A$7 | B13: =Data!$Q$6 | C13: =Data!Q7
A14: =Data!$A$7 | B14: =Data!$R$6 | C14: =Data!R7
A15: =Data!$A$7 | B15: =Data!$S$6 | C15: =Data!S7
A16: =Data!$A$7 | B16: =Data!$T$6 | C16: =Data!T7
A17: =Data!$A$7 | B17: =Data!$U$6 | C17: =Data!U7
A18: =Data!$A$7 | B18: =Data!$V$6 | C18: =Data!V7
A19: =Data!$A$7 | B19: =Data!$W$6 | C19: =Data!W7
A20: =Data!$A$7 | B20: =Data!$X$6 | C20: =Data!X7
A21: =Data!$A$7 | B21: =Data!$Y$6 | C21: =Data!Y7
A22: =Data!$A$7 | B22: =Data!$Z$6 | C22: =Data!Z7
A23: =Data!$A$7 | B23: =Data!$AA$6 | C23: =Data!AA7
A24: =Data!$A$7 | B24: =Data!$AB$6 | C24: =Data!AB7
A25: =Data!$A$7 | B25: =Data!$AC$6 | C25: =Data!AC7
A26: =Data!$A$7 | B26: =Data!$AD$6 | C26: =Data!AD7
A27: =Data!$A$7 | B27: =Data!$AE$6 | C27: =Data!AE7
A28: =Data!$A$7 | B28: =Data!$AF$6 | C28: =Data!AF7
A29: =Data!$A$7 | B29: =Data!$AG$6 | C29: =Data!AG7
A30: =Data!$A$7 | B30: =Data!$AH$6 | C30: =Data!AH7
A31: =Data!$A$7 | B31: =Data!$AI$6 | C31: =Data!AI7
A32: =Data!$A$7 | B32: =Data!$AJ$6 | C32: =Data!AJ7
A33: =Data!$A$7 | B33: =Data!$AK$6 | C33: =Data!AK7
A34: =Data!$A$7 | B34: =Data!$AL$6 | C34: =Data!AL7
A35: =Data!$A$7 | B35: =Data!$AM$6 | C35: =Data!AM7
A36: =Data!$A$7 | B36: =Data!$AN$6 | C36: =Data!AN7
A37: =Data!$A$7 | B37: =Data!$AO$6 | C37: =Data!AO7
A38: =Data!$A$7 | B38: =Data!$AP$6 | C38: =Data!AP7
A39: =Data!$A$7 | B39: =Data!$AQ$6 | C39: =Data!AQ7
A40: =Data!$A$7 | B40: =Data!$AR$6 | C40: =Data!AR7
A41: =Data!$A$7 | B41: =Data!$AS$6 | C41: =Data!AS7
...
